Workbook

Sheet README
A1: Enterprise project portfolio dataset
A2: Source workbook for the portfolio web app. Twelve related tables, one per sheet, all joined on stable IDs.
A4: How to read it
A5: Blue text | B5: Inputs. Safe to edit; the app and every formula update from them.
A6: Green text | B6: Lookups pulled from another table by ID (INDEX/MATCH).
A7: Black text | B7: Calculated. Do not overwrite; change the inputs or Settings instead.
A8: Yellow fill | B8: Key assumptions in Settings (RAG thresholds, contingency, as-of date).
A10: Tables
A11: tbl_Projects | B11: One row per project. Contract, schedule, earned value (EV, PV, CPI, SPI, EAC), margin, cash and RAG status.
A12: tbl_Resources | B12: People, rates, capacity and live utilization.
A13: tbl_Allocations | B13: Who is assigned to which project, when, and at what %. Planned vs actual hours.
A14: tbl_Estimates | B14: Effort estimates by phase. v1 Baseline for all; v2 Re-forecast where a project was re-planned.
A15: tbl_Budget | B15: Approved budget by project and cost category, with burn against actuals.
A16: tbl_Actuals | B16: Monthly cost ledger: timesheets, supplier invoices, expenses.
A17: tbl_Milestones | B17: Five milestones per project; Fixed Price milestones trigger billing.
A18: tbl_Invoices | B18: Invoices raised, payment status and aging.
A19: tbl_RAID | B19: Risks, issues, assumptions and dependencies with scoring and exposure.
A20: tbl_ChangeRequests | B20: Scope and budget changes. Only Approved CRs flow into project value and budget.
A21: tbl_Snapshots | B21: Month-end history (Jan-Aug 2026) for trend charts. Append-only static values.
A22: tbl_Clients | B22: Client accounts and payment terms.
... A24: tbl_Settings | B24: Thresholds and the AsOfDate. Named ranges make formulas readable (e.g. RAG_CostRed).
A26: Relationships
A27: ProjectID | B27: Projects -> Allocations, Estimates, Budget, Actuals, Milestones, Invoices, RAID, ChangeRequests, Snapshots
A28: EmployeeID | B28: Resources -> Allocations, Actuals, Projects.ProjectManagerID, RAID.OwnerID, ChangeRequests.RaisedByID
A29: ClientID | B29: Clients -> Projects (Invoices reach Clients through Projects)
A30: MilestoneID | B30: Milestones -> Invoices (Fixed Price billing)
A32: Built-in test scenarios
A33: Healthy | B33: P-1001, P-1004, P-1007, P-1009, P-1011, P-1012, P-1014, P-1016 - on budget and on time.
A34: Cost overrun | B34: P-1002 (severe - margin now Red), P-1013 (mild) - burning budget faster than progress.
A35: Schedule slip | B35: P-1003 (late), P-1010 (past baseline end, still open).
A36: Everything at risk | B36: P-1005, P-1017 (P-1017 forecasts a negative margin).
A37: Margin squeeze | B37: P-1006 (margin Amber). P-1015 has a CR that costs more than it earns but is still Green - a leading indicator to watch in trends.
A38: Other states | B38: P-1018 to P-1020 Completed (P-1019 finished 6 weeks late and over budget), P-1021 On Hold, P-1022 to P-1024 Planned.
A39: People | B39: A handful of people are overallocated (>100%) and some sit on the bench, to exercise the resource heatmap.
A40: Cash | B40: Aurora Retail and Bluewater Municipal have disputed invoices and Harbourview pays late, so every aging bucket is populated.
A42: For the app
A43: Read tables by name | B43: Read each tbl_* by name, not by sheet or cell range, so inserting rows or moving columns never breaks the sync.
A44: AsOfDate | B44: Fixed at 2026-09-11 so results are reproducible. Set it to =TODAY() for live use.
A45: Formula results | B45: Calculated values (EAC, RAG, HealthScore) are computed in the workbook, so the app can display them directly or recompute them itself.
A46: Data volume | B46: 24 projects, 63 people, ~1,400 ledger lines, ~100 invoices, ~70 RAID items.

Sheet Summary
A1: Portfolio summary
A2: ="As of "&TEXT(AsOfDate,"d mmm yyyy")&" | actuals to "&TEXT(ActualsCutoff,"d mmm yyyy") -> As of 11 Sep 2026 | actuals to 31 Aug 2026
A3: Every value is a live formula. DrillTarget describes the filter the app should open when the number is tapped.
A5: KPI | B5: Value | C5: DrillTarget
A6: Active projects | B6: =COUNTIF(Projects!$J$2:$J$500,"Active") -> 17 | C6: Projects | Status = Active
A7: Active contract value | B7: =SUMIFS(Projects!$W$2:$W$500,Projects!$J$2:$J$500,"Active") -> 16200000 | C7: Projects | Status = Active | sort CurrentContractValue desc
A8: Active budget (BAC) | B8: =SUMIFS(Projects!$Z$2:$Z$500,Projects!$J$2:$J$500,"Active") -> 10875900 | C8: Projects | Status = Active
A9: Actual cost to date (active) | B9: =SUMIFS(Projects!$AB$2:$AB$500,Projects!$J$2:$J$500,"Active") -> 7204719.1 | C9: Actuals | Project.Status = Active
A10: Estimate at completion (active) | B10: =SUMIFS(Projects!$AH$2:$AH$500,Projects!$J$2:$J$500,"Active") -> 11145600 | C10: Projects | Status = Active | sort VAC asc
A11: Forecast margin % (active) | B11: =IFERROR((B7-B10)/B7,0) -> 0.31200003 | C11: Projects | Status = Active | sort ForecastMarginPct asc
A12: Target margin % (weighted) | B12: =IFERROR(SUMPRODUCT((Projects!$J$2:$J$500="Active")*Projects!$W$2:$W$500*Projects!$S$2:$S$500)/B7,0) -> 0.36280247 | C12: Projects | Status = Active
A13: Red projects | B13: =COUNTIFS(Projects!$J$2:$J$500,"Active",Projects!$BC$2:$BC$500,"Red") -> 4 | C13: Projects | Status = Active AND OverallRAG = Red
A14: Amber projects | B14: =COUNTIFS(Projects!$J$2:$J$500,"Active",Projects!$BC$2:$BC$500,"Amber") -> 4 | C14: Projects | Status = Active AND OverallRAG = Amber
A15: Green projects | B15: =COUNTIFS(Projects!$J$2:$J$500,"Active",Projects!$BC$2:$BC$500,"Green") -> 9 | C15: Projects | Status = Active AND OverallRAG = Green
A16: Average health score | B16: =IFERROR(AVERAGEIFS(Projects!$BD$2:$BD$500,Projects!$J$2:$J$500,"Active"),0) -> 74.117647 | C16: Projects | Status = Active | sort HealthScore asc
A17: Average schedule slip (days) | B17: =IFERROR(AVERAGEIFS(Projects!$AO$2:$AO$500,Projects!$J$2:$J$500,"Active"),0) -> 17.941176 | C17: Projects | Status = Active | sort ScheduleSlipDays desc
A18: Overallocated people | B18: =COUNTIF(Resources!$R$2:$R$500,"Overallocated") -> 6 | C18: Resources | UtilizationStatus = Overallocated
A19: Under-utilized people | B19: =COUNTIF(Resources!$R$2:$R$500,"Under-utilized") -> 23 | C19: Resources | UtilizationStatus = Under-utilized
A20: Bench capacity (hrs/week) | B20: =SUM(Resources!$Q$2:$Q$500) -> 720 | C20: Resources | AvailableHrsPerWeek > 0
A21: Outstanding receivables | B21: =SUMIFS(Invoices!$F$2:$F$2000,Invoices!$K$2:$K$2000,"Outstanding")+SUMIFS(Invoices!$F$2:$F$2000,Invoices!$K$2:$K$2000,"Overdue") -> 1937308.9 | C21: Invoices | Status <> Paid
A22: Overdue receivables | B22: =SUMIFS(Invoices!$F$2:$F$2000,Invoices!$K$2:$K$2000,"Overdue") -> 789503.99 | C22: Invoices | Status = Overdue | sort DaysOverdue desc
A23: Unbilled WIP (active) | B23: =SUMIFS(Projects!$AS$2:$AS$500,Projects!$J$2:$J$500,"Active") -> 2117514.4 | C23: Projects | Status = Active | sort UnbilledWIP desc
A24: Open critical risks | B24: =COUNTIFS(RAID!$P$2:$P$2000,"Critical",RAID!$J$2:$J$2000,"<>Closed") -> 6 | C24: RAID | Severity = Critical AND Status <> Closed
A25: Open risk exposure (weighted) | B25: =SUMIFS(RAID!$Q$2:$Q$2000,RAID!$J$2:$J$2000,"Open")+SUMIFS(RAID!$Q$2:$Q$2000,RAID!$J$2:$J$2000,"Mitigating") -> 1632400 | C25: RAID | Status <> Closed | sort ExpectedExposure desc
A26: Pending change requests | B26: =COUNTIF(ChangeRequests!$P$2:$P$1000,"Yes") -> 8 | C26: ChangeRequests | IsPending = Yes
A27: Pending CR cost impact | B27: =SUMIFS(ChangeRequests!$I$2:$I$1000,ChangeRequests!$P$2:$P$1000,"Yes") -> 402000 | C27: ChangeRequests | IsPending = Yes
A28: Overdue milestones | B28: =COUNTIF(Milestones!$L$2:$L$2000,"Overdue") -> 4 | C28: Milestones | Status = Overdue
A30: By portfolio (active projects)
A31: Portfolio | B31: ActiveProjects | C31: ContractValue | D31: Budget | E31: ActualCost | F31: EAC | G31: ForecastMarginPct | H31: RedProjects | I31: AvgHealthScore
A32: Customer Experience | B32: =COUNTIFS(Projects!$E$2:$E$500,A32,Projects!$J$2:$J$500,"Active") -> 4 | C32: =SUMIFS(Projects!$W$2:$W$500,Projects!$E$2:$E$500,A32,Projects!$J$2:$J$500,"Active") -> 3345000 | D32: =SUMIFS(Projects!$Z$2:$Z$500,Projects!$E$2:$E$500,A32,Projects!$J$2:$J$500,"Active") -> 2264800 | E32: =SUMIFS(Projects!$AB$2:$AB$500,Projects!$E$2:$E$500,A32,Projects!$J$2:$J$500,"Active") -> 2077124.5 | F32: =SUMIFS(Projects!$AH$2:$AH$500,Projects!$E$2:$E$500,A32,Projects!$J$2:$J$500,"Active") -> 2459104.5 | G32: =IFERROR((C32-F32)/C32,0) -> 0.2648417 | H32: =COUNTIFS(Projects!$E$2:$E$500,A32,Projects!$J$2:$J$500,"Active",Projects!$BC$2:$BC$500,"Red") -> 2 | I32: =IFERROR(AVERAGEIFS(Projects!$BD$2:$BD$500,Projects!$E$2:$E$500,A32,Projects!$J$2:$J$500,"Active"),0) -> 50.75
A33: Data & AI | B33: =COUNTIFS(Projects!$E$2:$E$500,A33,Projects!$J$2:$J$500,"Active") -> 4 | C33: =SUMIFS(Projects!$W$2:$W$500,Projects!$E$2:$E$500,A33,Projects!$J$2:$J$500,"Active") -> 3765000 | D33: =SUMIFS(Projects!$Z$2:$Z$500,Projects!$E$2:$E$500,A33,Projects!$J$2:$J$500,"Active") -> 2449000 | E33: =SUMIFS(Projects!$AB$2:$AB$500,Projects!$E$2:$E$500,A33,Projects!$J$2:$J$500,"Active") -> 1294670.1 | F33: =SUMIFS(Projects!$AH$2:$AH$500,Projects!$E$2:$E$500,A33,Projects!$J$2:$J$500,"Active") -> 2569291.1 | G33: =IFERROR((C33-F33)/C33,0) -> 0.31758536 | H33: =COUNTIFS(Projects!$E$2:$E$500,A33,Projects!$J$2:$J$500,"Active",Projects!$BC$2:$BC$500,"Red") -> 1 | I33: =IFERROR(AVERAGEIFS(Projects!$BD$2:$BD$500,Projects!$E$2:$E$500,A33,Projects!$J$2:$J$500,"Active"),0) -> 70.75
A34: Cloud & Infrastructure | B34: =COUNTIFS(Projects!$E$2:$E$500,A34,Projects!$J$2:$J$500,"Active") -> 3 | C34: =SUMIFS(Projects!$W$2:$W$500,Projects!$E$2:$E$500,A34,Projects!$J$2:$J$500,"Active") -> 3370000 | D34: =SUMIFS(Projects!$Z$2:$Z$500,Projects!$E$2:$E$500,A34,Projects!$J$2:$J$500,"Active") -> 2218900 | E34: =SUMIFS(Projects!$AB$2:$AB$500,Projects!$E$2:$E$500,A34,Projects!$J$2:$J$500,"Active") -> 1631497.2 | F34: =SUMIFS(Projects!$AH$2:$AH$500,Projects!$E$2:$E$500,A34,Projects!$J$2:$J$500,"Active") -> 2165651.4 | G34: =IFERROR((C34-F34)/C34,0) -> 0.35737346 | H34: =COUNTIFS(Projects!$E$2:$E$500,A34,Projects!$J$2:$J$500,"Active",Projects!$BC$2:$BC$500,"Red") -> 0 | I34: =IFERROR(AVERAGEIFS(Projects!$BD$2:$BD$500,Projects!$E$2:$E$500,A34,Projects!$J$2:$J$500,"Active"),0) -> 89
A35: Digital Transformation | B35: =COUNTIFS(Projects!$E$2:$E$500,A35,Projects!$J$2:$J$500,"Active") -> 3 | C35: =SUMIFS(Projects!$W$2:$W$500,Projects!$E$2:$E$500,A35,Projects!$J$2:$J$500,"Active") -> 3945000 | D35: =SUMIFS(Projects!$Z$2:$Z$500,Projects!$E$2:$E$500,A35,Projects!$J$2:$J$500,"Active") -> 2739700 | E35: =SUMIFS(Projects!$AB$2:$AB$500,Projects!$E$2:$E$500,A35,Projects!$J$2:$J$500,"Active") -> 1489505.2 | F35: =SUMIFS(Projects!$AH$2:$AH$500,Projects!$E$2:$E$500,A35,Projects!$J$2:$J$500,"Active") -> 2677873 | G35: =IFERROR((C35-F35)/C35,0) -> 0.32119822 | H35: =COUNTIFS(Projects!$E$2:$E$500,A35,Projects!$J$2:$J$500,"Active",Projects!$BC$2:$BC$500,"Red") -> 0 | I35: =IFERROR(AVERAGEIFS(Projects!$BD$2:$BD$500,Projects!$E$2:$E$500,A35,Projects!$J$2:$J$500,"Active"),0) -> 89.666667
A36: Operational Excellence | B36: =COUNTIFS(Projects!$E$2:$E$500,A36,Projects!$J$2:$J$500,"Active") -> 3 | C36: =SUMIFS(Projects!$W$2:$W$500,Projects!$E$2:$E$500,A36,Projects!$J$2:$J$500,"Active") -> 1775000 | D36: =SUMIFS(Projects!$Z$2:$Z$500,Projects!$E$2:$E$500,A36,Projects!$J$2:$J$500,"Active") -> 1203500 | E36: =SUMIFS(Projects!$AB$2:$AB$500,Projects!$E$2:$E$500,A36,Projects!$J$2:$J$500,"Active") -> 711922.14 | F36: =SUMIFS(Projects!$AH$2:$AH$500,Projects!$E$2:$E$500,A36,Projects!$J$2:$J$500,"Active") -> 1273679.5 | G36: =IFERROR((C36-F36)/C36,0) -> 0.28243409 | H36: =COUNTIFS(Projects!$E$2:$E$500,A36,Projects!$J$2:$J$500,"Active",Projects!$BC$2:$BC$500,"Red") -> 1 | I36: =IFERROR(AVERAGEIFS(Projects!$BD$2:$BD$500,Projects!$E$2:$E$500,A36,Projects!$J$2:$J$500,"Active"),0) -> 79.333333
A38: Monthly trend (all projects)
A39: MonthEnd | B39: LabourCost | C39: NonLabourCost | D39: TotalCost | E39: HoursLogged | F39: BillableValue | G39: Invoiced | H39: Collected
A40: 45930 | B40: =SUMIFS(Actuals!$J$2:$J$6000,Actuals!$B$2:$B$6000,A40,Actuals!$D$2:$D$6000,"Labour") -> 226537.33 | C40: =SUMIFS(Actuals!$J$2:$J$6000,Actuals!$B$2:$B$6000,A40)-B40 -> 60878.79 | D40: =B40+C40 -> 287416.12 | E40: =SUMIFS(Actuals!$H$2:$H$6000,Actuals!$B$2:$B$6000,A40) -> 2508.1 | F40: =SUMIFS(Actuals!$M$2:$M$6000,Actuals!$B$2:$B$6000,A40) -> 440100 | G40: =SUMIFS(Invoices!$F$2:$F$2000,Invoices!$D$2:$D$2000,">"&EOMONTH(A40,-1),Invoices!$D$2:$D$2000,"<="&A40) -> 222055.56 | H40: =SUMIFS(Invoices!$F$2:$F$2000,Invoices!$G$2:$G$2000,">"&EOMONTH(A40,-1),Invoices!$G$2:$G$2000,"<="&A40) -> 124000
A41: 45961 | B41: =SUMIFS(Actuals!$J$2:$J$6000,Actuals!$B$2:$B$6000,A41,Actuals!$D$2:$D$6000,"Labour") -> 308954.55 | C41: =SUMIFS(Actuals!$J$2:$J$6000,Actuals!$B$2:$B$6000,A41)-B41 -> 60021.69 | D41: =B41+C41 -> 368976.24 | E41: =SUMIFS(Actuals!$H$2:$H$6000,Actuals!$B$2:$B$6000,A41) -> 3627.6 | F41: =SUMIFS(Actuals!$M$2:$M$6000,Actuals!$B$2:$B$6000,A41) -> 589236.5 | G41: =SUMIFS(Invoices!$F$2:$F$2000,Invoices!$D$2:$D$2000,">"&EOMONTH(A41,-1),Invoices!$D$2:$D$2000,"<="&A41) -> 327691.25 | H41: =SUMIFS(Invoices!$F$2:$F$2000,Invoices!$G$2:$G$2000,">"&EOMONTH(A41,-1),Invoices!$G$2:$G$2000,"<="&A41) -> 399635.69
A42: 45991 | B42: =SUMIFS(Actuals!$J$2:$J$6000,Actuals!$B$2:$B$6000,A42,Actuals!$D$2:$D$6000,"Labour") -> 338524.28 | C42: =SUMIFS(Actuals!$J$2:$J$6000,Actuals!$B$2:$B$6000,A42)-B42 -> 113878.9 | D42: =B42+C42 -> 452403.18 | E42: =SUMIFS(Actuals!$H$2:$H$6000,Actuals!$B$2:$B$6000,A42) -> 3956.9 | F42: =SUMIFS(Actuals!$M$2:$M$6000,Actuals!$B$2:$B$6000,A42) -> 648146.5 | G42: =SUMIFS(Invoices!$F$2:$F$2000,Invoices!$D$2:$D$2000,">"&EOMONTH(A42,-1),Invoices!$D$2:$D$2000,"<="&A42) -> 287739.67 | H42: =SUMIFS(Invoices!$F$2:$F$2000,Invoices!$G$2:$G$2000,">"&EOMONTH(A42,-1),Invoices!$G$2:$G$2000,"<="&A42) -> 161111.12
A43: 46022 | B43: =SUMIFS(Actuals!$J$2:$J$6000,Actuals!$B$2:$B$6000,A43,Actuals!$D$2:$D$6000,"Labour") -> 451604.36 | C43: =SUMIFS(Actuals!$J$2:$J$6000,Actuals!$B$2:$B$6000,A43)-B43 -> 76822.19 | D43: =B43+C43 -> 528426.55 | E43: =SUMIFS(Actuals!$H$2:$H$6000,Actuals!$B$2:$B$6000,A43) -> 5293.6 | F43: =SUMIFS(Actuals!$M$2:$M$6000,Actuals!$B$2:$B$6000,A43) -> 872226.5 | G43: =SUMIFS(Invoices!$F$2:$F$2000,Invoices!$D$2:$D$2000,">"&EOMONTH(A43,-1),Invoices!$D$2:$D$2000,"<="&A43) -> 1143552.1 | H43: =SUMIFS(Invoices!$F$2:$F$2000,Invoices!$G$2:$G$2000,">"&EOMONTH(A43,-1),Invoices!$G$2:$G$2000,"<="&A43) -> 528868.46
...

Sheet Projects
A1: ProjectID | B1: ProjectName | C1: ClientID | D1: ClientName | E1: Portfolio | F1: BusinessUnit | G1: ProjectManagerID | H1: ProjectManager | I1: ExecutiveSponsor | J1: Status | K1: Phase | L1: Priority | M1: ContractType | N1: StrategicScore | O1: BaselineStart | P1: BaselineEnd | Q1: ForecastEnd | R1: OriginalContractValue | S1: TargetMarginPct | T1: PctComplete | U1: LastStatusUpdate | V1: ApprovedCRRevenue | W1: CurrentContractValue | X1: BaselineBudget | Y1: ApprovedCRCost | Z1: CurrentBudget | AA1: ActualHours | AB1: ActualCost | AC1: ElapsedPct | AD1: EarnedValue | AE1: PlannedValue | AF1: CPI | AG1: SPI | AH1: EAC | AI1: ETC | AJ1: VAC | AK1: BudgetBurnPct | AL1: ForecastMarginAmt | AM1: ForecastMarginPct | AN1: MarginVsTarget | AO1: ScheduleSlipDays | AP1: DaysRemaining | AQ1: InvoicedToDate | AR1: CollectedToDate | AS1: UnbilledWIP | AT1: OpenRisks | AU1: OpenIssues | AV1: OpenRiskExposure | AW1: PendingCRs | AX1: TeamSize | AY1: NextMilestoneDate | AZ1: CostRAG | BA1: ScheduleRAG | BB1: MarginRAG | BC1: OverallRAG | BD1: HealthScore
A2: P-1001 | B2: Patient Portal Modernization | C2: C-101 | D2: =IFERROR(INDEX(Clients!$B$2:$B$200,MATCH(C2,Clients!$A$2:$A$200,0)),"Unknown client") -> Northgate Health Network | E2: Customer Experience | F2: Health & Public | G2: E-0003 | H2: =IFERROR(INDEX(Resources!$B$2:$B$500,MATCH(G2,Resources!$A$2:$A$500,0)),"") -> Aisha Tremblay | I2: Dr. Anne Keller | J2: Active | K2: Test & Deploy | L2: P2 | M2: Fixed Price | N2: 7 | O2: 45964 | P2: 46325 | Q2: 46329 | R2: 1100000 | S2: 0.34 | T2: 0.87 | U2: 46272 | V2: =SUMIFS(ChangeRequests!$H$2:$H$1000,ChangeRequests!$B$2:$B$1000,A2,ChangeRequests!$G$2:$G$1000,"Approved") -> 35000 | W2: =R2+V2 -> 1135000 | X2: =SUMIFS(Budget!$E$2:$E$2000,Budget!$B$2:$B$2000,A2) -> 726500 | Y2: =SUMIFS(ChangeRequests!$I$2:$I$1000,ChangeRequests!$B$2:$B$1000,A2,ChangeRequests!$G$2:$G$1000,"Approved") -> 22000 | Z2: =X2+Y2 -> 748500 | AA2: =SUMIFS(Actuals!$H$2:$H$6000,Actuals!$C$2:$C$6000,A2) -> 5585 | AB2: =SUMIFS(Actuals!$J$2:$J$6000,Actuals!$C$2:$C$6000,A2) -> 569689.28 | AC2: =IF(J2="Completed",1,IF(AsOfDate<=O2,0,MIN(1,(AsOfDate-O2)/MAX(1,P2-O2)))) -> 0.86426593 | AD2: =T2*Z2 -> 651195 | AE2: =AC2*Z2 -> 646903.05 | AF2: =IF(AB2=0,1,AD2/AB2) -> 1.1430705 | AG2: =IF(AE2=0,1,AD2/AE2) -> 1.0066346 | AH2: =IF(J2="Completed",AB2,IF(T2<0.05,MAX(Z2,AB2),AB2/T2)) -> 654815.26 | AI2: =MAX(0,AH2-AB2) -> 85125.984 | AJ2: =Z2-AH2 -> 93684.736 | AK2: =IF(Z2=0,0,AB2/Z2) -> 0.76110792 | AL2: =W2-AH2 -> 480184.74 | AM2: =IF(W2=0,0,AL2/W2) -> 0.42307025 | AN2: =AM2-S2 -> 0.083070252 | AO2: =Q2-P2 -> 4 | AP2: =IF(J2="Completed",0,MAX(0,Q2-AsOfDate)) -> 53 | AQ2: =SUMIFS(Invoices!$F$2:$F$2000,Invoices!$B$2:$B$2000,A2) -> 660000 | AR2: =SUMIFS(Invoices!$F$2:$F$2000,Invoices!$B$2:$B$2000,A2,Invoices!$K$2:$K$2000,"Paid") -> 660000 | AS2: =T2*W2-AQ2 -> 327450 | AT2: =COUNTIFS(RAID!$B$2:$B$2000,A2,RAID!$C$2:$C$2000,"Risk",RAID!$J$2:$J$2000,"<>Closed") -> 0 | AU2: =COUNTIFS(RAID!$B$2:$B$2000,A2,RAID!$C$2:$C$2000,"Issue",RAID!$J$2:$J$2000,"<>Closed") -> 0 | AV2: =SUMIFS(RAID!$Q$2:$Q$2000,RAID!$B$2:$B$2000,A2,RAID!$J$2:$J$2000,"<>Closed") -> 0 | AW2: =COUNTIFS(ChangeRequests!$B$2:$B$1000,A2,ChangeRequests!$P$2:$P$1000,"Yes") -> 0 | AX2: =COUNTIFS(Allocations!$B$2:$B$2000,A2,Allocations!$K$2:$K$2000,"Yes") -> 4 | AY2: =IF(COUNTIFS(Milestones!$B$2:$B$2000,A2,Milestones!$L$2:$L$2000,"<>Completed")=0,"",_xlfn.MINIFS(Milestones!$F$2:$F$2000,Milestones!$B$2:$B$2000,A2,Milestones!$L$2:$L$2000,"<>Completed")) -> 46293 | AZ2: =IF(J2="Planned","N/A",IF(AK2-T2>RAG_CostRed,"Red",IF(AK2-T2>RAG_CostAmber,"Amber","Green"))) -> Green | BA2: =IF(J2="Planned","N/A",IF(AO2>RAG_ScheduleRedDays,"Red",IF(AO2>RAG_ScheduleAmberDays,"Amber","Green"))) -> Green | BB2: =IF(J2="Planned","N/A",IF(AM2<MarginFloor,"Red",IF(AM2<S2-MarginTolerance,"Amber","Green"))) -> Green | BC2: =IF(J2="Planned","N/A",IF(OR(AZ2="Red",BA2="Red",BB2="Red"),"Red",IF(OR(AZ2="Amber",BA2="Amber",BB2="Amber"),"Amber","Green"))) -> Green | BD2: =IF(J2="Planned","",MAX(0,ROUND(100-MAX(0,AK2-T2)*150-MAX(0,AO2)*0.4-MAX(0,S2-AM2)*150,0))) -> 98
A3: P-1002 | B3: Claims Automation Engine | C3: C-102 | D3: =IFERROR(INDEX(Clients!$B$2:$B$200,MATCH(C3,Clients!$A$2:$A$200,0)),"Unknown client") -> Crestline Insurance | E3: Operational Excellence | F3: Financial Services | G3: E-0004 | H3: =IFERROR(INDEX(Resources!$B$2:$B$500,MATCH(G3,Resources!$A$2:$A$500,0)),"") -> Liam Roy | I3: Robert Lindqvist | J3: Active | K3: Execute | L3: P1 | M3: Fixed Price | N3: 7 | O3: 46034 | P3: 46374 | Q3: 46391 | R3: 685000 | S3: 0.32 | T3: 0.57 | U3: 46271 | V3: =SUMIFS(ChangeRequests!$H$2:$H$1000,ChangeRequests!$B$2:$B$1000,A3,ChangeRequests!$G$2:$G$1000,"Approved") -> 85000 | W3: =R3+V3 -> 770000 | X3: =SUMIFS(Budget!$E$2:$E$2000,Budget!$B$2:$B$2000,A3) -> 466100 | Y3: =SUMIFS(ChangeRequests!$I$2:$I$1000,ChangeRequests!$B$2:$B$1000,A3,ChangeRequests!$G$2:$G$1000,"Approved") -> 70000 | Z3: =X3+Y3 -> 536100 | AA3: =SUMIFS(Actuals!$H$2:$H$6000,Actuals!$C$2:$C$6000,A3) -> 4086.4 | AB3: =SUMIFS(Actuals!$J$2:$J$6000,Actuals!$C$2:$C$6000,A3) -> 382554.58 | AC3: =IF(J3="Completed",1,IF(AsOfDate<=O3,0,MIN(1,(AsOfDate-O3)/MAX(1,P3-O3)))) -> 0.71176471 | AD3: =T3*Z3 -> 305577 | AE3: =AC3*Z3 -> 381577.06 | AF3: =IF(AB3=0,1,AD3/AB3) -> 0.79878014 | AG3: =IF(AE3=0,1,AD3/AE3) -> 0.80082645 | AH3: =IF(J3="Completed",AB3,IF(T3<0.05,MAX(Z3,AB3),AB3/T3)) -> 671148.39 | AI3: =MAX(0,AH3-AB3) -> 288593.81 | AJ3: =Z3-AH3 -> -135048.39 | AK3: =IF(Z3=0,0,AB3/Z3) -> 0.7135881 | AL3: =W3-AH3 -> 98851.614 | AM3: =IF(W3=0,0,AL3/W3) -> 0.12837872 | AN3: =AM3-S3 -> -0.19162128 | AO3: =Q3-P3 -> 17 | AP3: =IF(J3="Completed",0,MAX(0,Q3-AsOfDate)) -> 115 | AQ3: =SUMIFS(Invoices!$F$2:$F$2000,Invoices!$B$2:$B$2000,A3) -> 205500 | AR3: =SUMIFS(Invoices!$F$2:$F$2000,Invoices!$B$2:$B$2000,A3,Invoices!$K$2:$K$2000,"Paid") -> 205500 | AS3: =T3*W3-AQ3 -> 233400 | AT3: =COUNTIFS(RAID!$B$2:$B$2000,A3,RAID!$C$2:$C$2000,"Risk",RAID!$J$2:$J$2000,"<>Closed") -> 3 | AU3: =COUNTIFS(RAID!$B$2:$B$2000,A3,RAID!$C$2:$C$2000,"Issue",RAID!$J$2:$J$2000,"<>Closed") -> 0 | AV3: =SUMIFS(RAID!$Q$2:$Q$2000,RAID!$B$2:$B$2000,A3,RAID!$J$2:$J$2000,"<>Closed") -> 105800 | AW3: =COUNTIFS(ChangeRequests!$B$2:$B$1000,A3,ChangeRequests!$P$2:$P$1000,"Yes") -> 1 | AX3: =COUNTIFS(Allocations!$B$2:$B$2000,A3,Allocations!$K$2:$K$2000,"Yes") -> 6 | AY3: =IF(COUNTIFS(Milestones!$B$2:$B$2000,A3,Milestones!$L$2:$L$2000,"<>Completed")=0,"",_xlfn.MINIFS(Milestones!$F$2:$F$2000,Milestones!$B$2:$B$2000,A3,Milestones!$L$2:$L$2000,"<>Completed")) -> 46269 | AZ3: =IF(J3="Planned","N/A",IF(AK3-T3>RAG_CostRed,"Red",IF(AK3-T3>RAG_CostAmber,"Amber","Green"))) -> Amber | BA3: =IF(J3="Planned","N/A",IF(AO3>RAG_ScheduleRedDays,"Red",IF(AO3>RAG_ScheduleAmberDays,"Amber","Green"))) -> Amber | BB3: =IF(J3="Planned","N/A",IF(AM3<MarginFloor,"Red",IF(AM3<S3-MarginTolerance,"Amber","Green"))) -> Red | BC3: =IF(J3="Planned","N/A",IF(OR(AZ3="Red",BA3="Red",BB3="Red"),"Red",IF(OR(AZ3="Amber",BA3="Amber",BB3="Amber"),"Amber","Green"))) -> Red | BD3: =IF(J3="Planned","",MAX(0,ROUND(100-MAX(0,AK3-T3)*150-MAX(0,AO3)*0.4-MAX(0,S3-AM3)*150,0))) -> 43
A4: P-1003 | B4: Enterprise Data Lakehouse | C4: C-103 | D4: =IFERROR(INDEX(Clients!$B$2:$B$200,MATCH(C4,Clients!$A$2:$A$200,0)),"Unknown client") -> Maple Ridge Financial | E4: Data & AI | F4: Financial Services | G4: E-0005 | H4: =IFERROR(INDEX(Resources!$B$2:$B$500,MATCH(G4,Resources!$A$2:$A$500,0)),"") -> Mei Fraser | I4: Janet Osei | J4: Active | K4: Execute | L4: P3 | M4: Time & Materials | N4: 10 | O4: 45908 | P4: 46353 | Q4: 46394 | R4: 1165000 | S4: 0.42 | T4: 0.66 | U4: 46270 | V4: =SUMIFS(ChangeRequests!$H$2:$H$1000,ChangeRequests!$B$2:$B$1000,A4,ChangeRequests!$G$2:$G$1000,"Approved") -> 180000 | W4: =R4+V4 -> 1345000 | X4: =SUMIFS(Budget!$E$2:$E$2000,Budget!$B$2:$B$2000,A4) -> 769600 | Y4: =SUMIFS(ChangeRequests!$I$2:$I$1000,ChangeRequests!$B$2:$B$1000,A4,ChangeRequests!$G$2:$G$1000,"Approved") -> 110000 | Z4: =X4+Y4 -> 879600 | AA4: =SUMIFS(Actuals!$H$2:$H$6000,Actuals!$C$2:$C$6000,A4) -> 5722.4 | AB4: =SUMIFS(Actuals!$J$2:$J$6000,Actuals!$C$2:$C$6000,A4) -> 614808.15 | AC4: =IF(J4="Completed",1,IF(AsOfDate<=O4,0,MIN(1,(AsOfDate-O4)/MAX(1,P4-O4)))) -> 0.82696629 | AD4: =T4*Z4 -> 580536 | AE4: =AC4*Z4 -> 727399.55 | AF4: =IF(AB4=0,1,AD4/AB4) -> 0.94425554 | AG4: =IF(AE4=0,1,AD4/AE4) -> 0.79809783 | AH4: =IF(J4="Completed",AB4,IF(T4<0.05,MAX(Z4,AB4),AB4/T4)) -> 931527.5 | AI4: =MAX(0,AH4-AB4) -> 316719.35 | AJ4: =Z4-AH4 -> -51927.5 | AK4: =IF(Z4=0,0,AB4/Z4) -> 0.69896334 | AL4: =W4-AH4 -> 413472.5 | AM4: =IF(W4=0,0,AL4/W4) -> 0.3074145 | AN4: =AM4-S4 -> -0.1125855 | AO4: =Q4-P4 -> 41 | AP4: =IF(J4="Completed",0,MAX(0,Q4-AsOfDate)) -> 118 | AQ4: =SUMIFS(Invoices!$F$2:$F$2000,Invoices!$B$2:$B$2000,A4) -> 1061258.4 | AR4: =SUMIFS(Invoices!$F$2:$F$2000,Invoices!$B$2:$B$2000,A4,Invoices!$K$2:$K$2000,"Paid") -> 875084.78 | AS4: =T4*W4-AQ4 -> -173558.45 | AT4: =COUNTIFS(RAID!$B$2:$B$2000,A4,RAID!$C$2:$C$2000,"Risk",RAID!$J$2:$J$2000,"<>Closed") -> 2 | AU4: =COUNTIFS(RAID!$B$2:$B$2000,A4,RAID!$C$2:$C$2000,"Issue",RAID!$J$2:$J$2000,"<>Closed") -> 0 | AV4: =SUMIFS(RAID!$Q$2:$Q$2000,RAID!$B$2:$B$2000,A4,RAID!$J$2:$J$2000,"<>Closed") -> 108800 | AW4: =COUNTIFS(ChangeRequests!$B$2:$B$1000,A4,ChangeRequests!$P$2:$P$1000,"Yes") -> 1 | AX4: =COUNTIFS(Allocations!$B$2:$B$2000,A4,Allocations!$K$2:$K$2000,"Yes") -> 5 | AY4: =IF(COUNTIFS(Milestones!$B$2:$B$2000,A4,Milestones!$L$2:$L$2000,"<>Completed")=0,"",_xlfn.MINIFS(Milestones!$F$2:$F$2000,Milestones!$B$2:$B$2000,A4,Milestones!$L$2:$L$2000,"<>Completed")) -> 46263 | AZ4: =IF(J4="Planned","N/A",IF(AK4-T4>RAG_CostRed,"Red",IF(AK4-T4>RAG_CostAmber,"Amber","Green"))) -> Green | BA4: =IF(J4="Planned","N/A",IF(AO4>RAG_ScheduleRedDays,"Red",IF(AO4>RAG_ScheduleAmberDays,"Amber","Green"))) -> Amber | BB4: =IF(J4="Planned","N/A",IF(AM4<MarginFloor,"Red",IF(AM4<S4-MarginTolerance,"Amber","Green"))) -> Amber | BC4: =IF(J4="Planned","N/A",IF(OR(AZ4="Red",BA4="Red",BB4="Red"),"Red",IF(OR(AZ4="Amber",BA4="Amber",BB4="Amber"),"Amber","Green"))) -> Amber | BD4: =IF(J4="Planned","",MAX(0,ROUND(100-MAX(0,AK4-T4)*150-MAX(0,AO4)*0.4-MAX(0,S4-AM4)*150,0))) -> 61
A5: P-1004 | B5: Cloud Migration Wave 2 | C5: C-104 | D5: =IFERROR(INDEX(Clients!$B$2:$B$200,MATCH(C5,Clients!$A$2:$A$200,0)),"Unknown client") -> Harbourview Logistics | E5: Cloud & Infrastructure | F5: Industrial | G5: E-0006 | H5: =IFERROR(INDEX(Resources!$B$2:$B$500,MATCH(G5,Resources!$A$2:$A$500,0)),"") -> Noah Rahimi | I5: Paul Moreau | J5: Active | K5: Execute | L5: P1 | M5: Fixed Price | N5: 6 | O5: 46055 | P5: 46416 | Q5: 46422 | R5: 1155000 | S5: 0.36 | T5: 0.61 | U5: 46269 | V5: =SUMIFS(ChangeRequests!$H$2:$H$1000,ChangeRequests!$B$2:$B$1000,A5,ChangeRequests!$G$2:$G$1000,"Approved") -> 0 | W5: =R5+V5 -> 1155000 | X5: =SUMIFS(Budget!$E$2:$E$2000,Budget!$B$2:$B$2000,A5) -> 738500 | Y5: =SUMIFS(ChangeRequests!$I$2:$I$1000,ChangeRequests!$B$2:$B$1000,A5,ChangeRequests!$G$2:$G$1000,"Approved") -> 0 | Z5: =X5+Y5 -> 738500 | AA5: =SUMIFS(Actuals!$H$2:$H$6000,Actuals!$C$2:$C$6000,A5) -> 2972.5 | AB5: =SUMIFS(Actuals!$J$2:$J$6000,Actuals!$C$2:$C$6000,A5) -> 440837.72 | AC5: =IF(J5="Completed",1,IF(AsOfDate<=O5,0,MIN(1,(AsOfDate-O5)/MAX(1,P5-O5)))) -> 0.61218837 | AD5: =T5*Z5 -> 450485 | AE5: =AC5*Z5 -> 452101.11 | AF5: =IF(AB5=0,1,AD5/AB5) -> 1.021884 | AG5: =IF(AE5=0,1,AD5/AE5) -> 0.99642534 | AH5: =IF(J5="Completed",AB5,IF(T5<0.05,MAX(Z5,AB5),AB5/T5)) -> 722684.79 | AI5: =MAX(0,AH5-AB5) -> 281847.07 | AJ5: =Z5-AH5 -> 15815.213 | AK5: =IF(Z5=0,0,AB5/Z5) -> 0.59693666 | AL5: =W5-AH5 -> 432315.21 | AM5: =IF(W5=0,0,AL5/W5) -> 0.37429889 | AN5: =AM5-S5 -> 0.014298886 | AO5: =Q5-P5 -> 6 | AP5: =IF(J5="Completed",0,MAX(0,Q5-AsOfDate)) -> 146 | AQ5: =SUMIFS(Invoices!$F$2:$F$2000,Invoices!$B$2:$B$2000,A5) -> 346500 | AR5: =SUMIFS(Invoices!$F$2:$F$2000,Invoices!$B$2:$B$2000,A5,Invoices!$K$2:$K$2000,"Paid") -> 346500 | AS5: =T5*W5-AQ5 -> 358050 | AT5: =COUNTIFS(RAID!$B$2:$B$2000,A5,RAID!$C$2:$C$2000,"Risk",RAID!$J$2:$J$2000,"<>Closed") -> 0 | AU5: =COUNTIFS(RAID!$B$2:$B$2000,A5,RAID!$C$2:$C$2000,"Issue",RAID!$J$2:$J$2000,"<>Closed") -> 1 | AV5: =SUMIFS(RAID!$Q$2:$Q$2000,RAID!$B$2:$B$2000,A5,RAID!$J$2:$J$2000,"<>Closed") -> 65400 | AW5: =COUNTIFS(ChangeRequests!$B$2:$B$1000,A5,ChangeRequests!$P$2:$P$1000,"Yes") -> 1 | AX5: =COUNTIFS(Allocations!$B$2:$B$2000,A5,Allocations!$K$2:$K$2000,"Yes") -> 4 | AY5: =IF(COUNTIFS(Milestones!$B$2:$B$2000,A5,Milestones!$L$2:$L$2000,"<>Completed")=0,"",_xlfn.MINIFS(Milestones!$F$2:$F$2000,Milestones!$B$2:$B$2000,A5,Milestones!$L$2:$L$2000,"<>Completed")) -> 46310 | AZ5: =IF(J5="Planned","N/A",IF(AK5-T5>RAG_CostRed,"Red",IF(AK5-T5>RAG_CostAmber,"Amber","Green"))) -> Green | BA5: =IF(J5="Planned","N/A",IF(AO5>RAG_ScheduleRedDays,"Red",IF(AO5>RAG_ScheduleAmberDays,"Amber","Green"))) -> Green | BB5: =IF(J5="Planned","N/A",IF(AM5<MarginFloor,"Red",IF(AM5<S5-MarginTolerance,"Amber","Green"))) -> Green | BC5: =IF(J5="Planned","N/A",IF(OR(AZ5="Red",BA5="Red",BB5="Red"),"Red",IF(OR(AZ5="Amber",BA5="Amber",BB5="Amber"),"Amber","Green"))) -> Green | BD5: =IF(J5="Planned","",MAX(0,ROUND(100-MAX(0,AK5-T5)*150-MAX(0,AO5)*0.4-MAX(0,S5-AM5)*150,0))) -> 98
A6: P-1005 | B6: Fraud Detection ML Platform | C6: C-105 | D6: =IFERROR(INDEX(Clients!$B$2:$B$200,MATCH(C6,Clients!$A$2:$A$200,0)),"Unknown client") -> Ironbridge Capital | E6: Data & AI | F6: Financial Services | G6: E-0007 | H6: =IFERROR(INDEX(Resources!$B$2:$B$500,MATCH(G6,Resources!$A$2:$A$500,0)),"") -> Fatima Cohen | I6: Karen Whitfield | J6: Active | K6: Execute | L6: P1 | M6: Fixed Price | N6: 5 | O6: 46083 | P6: 46444 | Q6: 46510 | R6: 740000 | S6: 0.38 | T6: 0.4 | U6: 46273 | V6: =SUMIFS(ChangeRequests!$H$2:$H$1000,ChangeRequests!$B$2:$B$1000,A6,ChangeRequests!$G$2:$G$1000,"Approved") -> 120000 | W6: =R6+V6 -> 860000 | X6: =SUMIFS(Budget!$E$2:$E$2000,Budget!$B$2:$B$2000,A6) -> 459200 | Y6: =SUMIFS(ChangeRequests!$I$2:$I$1000,ChangeRequests!$B$2:$B$1000,A6,ChangeRequests!$G$2:$G$1000,"Approved") -> 95000 | Z6: =X6+Y6 -> 554200 | AA6: =SUMIFS(Actuals!$H$2:$H$6000,Actuals!$C$2:$C$6000,A6) -> 2942.1 | AB6: =SUMIFS(Actuals!$J$2:$J$6000,Actuals!$C$2:$C$6000,A6) -> 289303.7 | AC6: =IF(J6="Completed",1,IF(AsOfDate<=O6,0,MIN(1,(AsOfDate-O6)/MAX(1,P6-O6)))) -> 0.53462604 | AD6: =T6*Z6 -> 221680 | AE6: =AC6*Z6 -> 296289.75 | AF6: =IF(AB6=0,1,AD6/AB6) -> 0.76625359 | AG6: =IF(AE6=0,1,AD6/AE6) -> 0.74818653 | AH6: =IF(J6="Completed",AB6,IF(T6<0.05,MAX(Z6,AB6),AB6/T6)) -> 723259.25 | AI6: =MAX(0,AH6-AB6) -> 433955.55 | AJ6: =Z6-AH6 -> -169059.25 | AK6: =IF(Z6=0,0,AB6/Z6) -> 0.52202039 | AL6: =W6-AH6 -> 136740.75 | AM6: =IF(W6=0,0,AL6/W6) -> 0.15900087 | AN6: =AM6-S6 -> -0.22099913 | AO6: =Q6-P6 -> 66 | AP6: =IF(J6="Completed",0,MAX(0,Q6-AsOfDate)) -> 234 | AQ6: =SUMIFS(Invoices!$F$2:$F$2000,Invoices!$B$2:$B$2000,A6) -> 222000 | AR6: =SUMIFS(Invoices!$F$2:$F$2000,Invoices!$B$2:$B$2000,A6,Invoices!$K$2:$K$2000,"Paid") -> 222000 | AS6: =T6*W6-AQ6 -> 122000 | AT6: =COUNTIFS(RAID!$B$2:$B$2000,A6,RAID!$C$2:$C$2000,"Risk",RAID!$J$2:$J$2000,"<>Closed") -> 2 | AU6: =COUNTIFS(RAID!$B$2:$B$2000,A6,RAID!$C$2:$C$2000,"Issue",RAID!$J$2:$J$2000,"<>Closed") -> 1 | AV6: =SUMIFS(RAID!$Q$2:$Q$2000,RAID!$B$2:$B$2000,A6,RAID!$J$2:$J$2000,"<>Closed") -> 337800 | AW6: =COUNTIFS(ChangeRequests!$B$2:$B$1000,A6,ChangeRequests!$P$2:$P$1000,"Yes") -> 2 | AX6: =COUNTIFS(Allocations!$B$2:$B$2000,A6,Allocations!$K$2:$K$2000,"Yes") -> 6 | AY6: =IF(COUNTIFS(Milestones!$B$2:$B$2000,A6,Milestones!$L$2:$L$2000,"<>Completed")=0,"",_xlfn.MINIFS(Milestones!$F$2:$F$2000,Milestones!$B$2:$B$2000,A6,Milestones!$L$2:$L$2000,"<>Completed")) -> 46377 | AZ6: =IF(J6="Planned","N/A",IF(AK6-T6>RAG_CostRed,"Red",IF(AK6-T6>RAG_CostAmber,"Amber","Green"))) -> Amber | BA6: =IF(J6="Planned","N/A",IF(AO6>RAG_ScheduleRedDays,"Red",IF(AO6>RAG_ScheduleAmberDays,"Amber","Green"))) -> Red | BB6: =IF(J6="Planned","N/A",IF(AM6<MarginFloor,"Red",IF(AM6<S6-MarginTolerance,"Amber","Green"))) -> Amber | BC6: =IF(J6="Planned","N/A",IF(OR(AZ6="Red",BA6="Red",BB6="Red"),"Red",IF(OR(AZ6="Amber",BA6="Amber",BB6="Amber"),"Amber","Green"))) -> Red | BD6: =IF(J6="Planned","",MAX(0,ROUND(100-MAX(0,AK6-T6)*150-MAX(0,AO6)*0.4-MAX(0,S6-AM6)*150,0))) -> 22
A7: P-1006 | B7: Omnichannel Commerce Replatform | C7: C-106 | D7: =IFERROR(INDEX(Clients!$B$2:$B$200,MATCH(C7,Clients!$A$2:$A$200,0)),"Unknown client") -> Aurora Retail Group | E7: Customer Experience | F7: Consumer | G7: E-0009 | H7: =IFERROR(INDEX(Resources!$B$2:$B$500,MATCH(G7,Resources!$A$2:$A$500,0)),"") -> Olivia Silva | I7: Luc Bergeron | J7: Active | K7: Test & Deploy | L7: P2 | M7: Fixed Price | N7: 7 | O7: 45936 | P7: 46290 | Q7: 46300 | R7: 940000 | S7: 0.38 | T7: 0.92 | U7: 46272 | V7: =SUMIFS(ChangeRequests!$H$2:$H$1000,ChangeRequests!$B$2:$B$1000,A7,ChangeRequests!$G$2:$G$1000,"Approved") -> 40000 | W7: =R7+V7 -> 980000 | X7: =SUMIFS(Budget!$E$2:$E$2000,Budget!$B$2:$B$2000,A7) -> 582300 | Y7: =SUMIFS(ChangeRequests!$I$2:$I$1000,ChangeRequests!$B$2:$B$1000,A7,ChangeRequests!$G$2:$G$1000,"Approved") -> 48000 | Z7: =X7+Y7 -> 630300 | AA7: =SUMIFS(Actuals!$H$2:$H$6000,Actuals!$C$2:$C$6000,A7) -> 7769.4 | AB7: =SUMIFS(Actuals!$J$2:$J$6000,Actuals!$C$2:$C$6000,A7) -> 622397.49 | AC7: =IF(J7="Completed",1,IF(AsOfDate<=O7,0,MIN(1,(AsOfDate-O7)/MAX(1,P7-O7)))) -> 0.96045198 | AD7: =T7*Z7 -> 579876 | AE7: =AC7*Z7 -> 605372.88 | AF7: =IF(AB7=0,1,AD7/AB7) -> 0.93168114 | AG7: =IF(AE7=0,1,AD7/AE7) -> 0.95788235 | AH7: =IF(J7="Completed",AB7,IF(T7<0.05,MAX(Z7,AB7),AB7/T7)) -> 676519.01 | AI7: =MAX(0,AH7-AB7) -> 54121.521 | AJ7: =Z7-AH7 -> -46219.011 | AK7: =IF(Z7=0,0,AB7/Z7) -> 0.9874623 | AL7: =W7-AH7 -> 303480.99 | AM7: =IF(W7=0,0,AL7/W7) -> 0.30967448 | AN7: =AM7-S7 -> -0.070325521 | AO7: =Q7-P7 -> 10 | AP7: =IF(J7="Completed",0,MAX(0,Q7-AsOfDate)) -> 24 | AQ7: =SUMIFS(Invoices!$F$2:$F$2000,Invoices!$B$2:$B$2000,A7) -> 752000 | AR7: =SUMIFS(Invoices!$F$2:$F$2000,Invoices!$B$2:$B$2000,A7,Invoices!$K$2:$K$2000,"Paid") -> 282000 | AS7: =T7*W7-AQ7 -> 149600 | AT7: =COUNTIFS(RAID!$B$2:$B$2000,A7,RAID!$C$2:$C$2000,"Risk",RAID!$J$2:$J$2000,"<>Closed") -> 0 | AU7: =COUNTIFS(RAID!$B$2:$B$2000,A7,RAID!$C$2:$C$2000,"Issue",RAID!$J$2:$J$2000,"<>Closed") -> 1 | AV7: =SUMIFS(RAID!$Q$2:$Q$2000,RAID!$B$2:$B$2000,A7,RAID!$J$2:$J$2000,"<>Closed") -> 21000 | AW7: =COUNTIFS(ChangeRequests!$B$2:$B$1000,A7,ChangeRequests!$P$2:$P$1000,"Yes") -> 0 | AX7: =COUNTIFS(Allocations!$B$2:$B$2000,A7,Allocations!$K$2:$K$2000,"Yes") -> 4 | AY7: =IF(COUNTIFS(Milestones!$B$2:$B$2000,A7,Milestones!$L$2:$L$2000,"<>Completed")=0,"",_xlfn.MINIFS(Milestones!$F$2:$F$2000,Milestones!$B$2:$B$2000,A7,Milestones!$L$2:$L$2000,"<>Completed")) -> 46300 | AZ7: =IF(J7="Planned","N/A",IF(AK7-T7>RAG_CostRed,"Red",IF(AK7-T7>RAG_CostAmber,"Amber","Green"))) -> Green | BA7: =IF(J7="Planned","N/A",IF(AO7>RAG_ScheduleRedDays,"Red",IF(AO7>RAG_ScheduleAmberDays,"Amber","Green"))) -> Green | BB7: =IF(J7="Planned","N/A",IF(AM7<MarginFloor,"Red",IF(AM7<S7-MarginTolerance,"Amber","Green"))) -> Amber | BC7: =IF(J7="Planned","N/A",IF(OR(AZ7="Red",BA7="Red",BB7="Red"),"Red",IF(OR(AZ7="Amber",BA7="Amber",BB7="Amber"),"Amber","Green"))) -> Amber | BD7: =IF(J7="Planned","",MAX(0,ROUND(100-MAX(0,AK7-T7)*150-MAX(0,AO7)*0.4-MAX(0,S7-AM7)*150,0))) -> 75
A8: P-1007 | B8: Student Information System Upgrade | C8: C-107 | D8: =IFERROR(INDEX(Clients!$B$2:$B$200,MATCH(C8,Clients!$A$2:$A$200,0)),"Unknown client") -> Pinecrest University | E8: Digital Transformation | F8: Health & Public | G8: E-0008 | H8: =IFERROR(INDEX(Resources!$B$2:$B$500,MATCH(G8,Resources!$A$2:$A$500,0)),"") -> Ethan Park | I8: Prof. Ellen Shaw | J8: Active | K8: Execute | L8: P1 | M8: Fixed Price | N8: 10 | O8: 46118 | P8: 46472 | Q8: 46475 | R8: 970000 | S8: 0.34 | T8: 0.43 | U8: 46271 | V8: =SUMIFS(ChangeRequests!$H$2:$H$1000,ChangeRequests!$B$2:$B$1000,A8,ChangeRequests!$G$2:$G$1000,"Approved") -> 0 | W8: =R8+V8 -> 970000 | X8: =SUMIFS(Budget!$E$2:$E$2000,Budget!$B$2:$B$2000,A8) -> 639400 | Y8: =SUMIFS(ChangeRequests!$I$2:$I$1000,ChangeRequests!$B$2:$B$1000,A8,ChangeRequests!$G$2:$G$1000,"Approved") -> 0 | Z8: =X8+Y8 -> 639400 | AA8: =SUMIFS(Actuals!$H$2:$H$6000,Actuals!$C$2:$C$6000,A8) -> 2307 | AB8: =SUMIFS(Actuals!$J$2:$J$6000,Actuals!$C$2:$C$6000,A8) -> 249953.93 | AC8: =IF(J8="Completed",1,IF(AsOfDate<=O8,0,MIN(1,(AsOfDate-O8)/MAX(1,P8-O8)))) -> 0.44632768 | AD8: =T8*Z8 -> 274942 | AE8: =AC8*Z8 -> 285381.92 | AF8: =IF(AB8=0,1,AD8/AB8) -> 1.0999707 | AG8: =IF(AE8=0,1,AD8/AE8) -> 0.96341772 | AH8: =IF(J8="Completed",AB8,IF(T8<0.05,MAX(Z8,AB8),AB8/T8)) -> 581288.21 | AI8: =MAX(0,AH8-AB8) -> 331334.28 | AJ8: =Z8-AH8 -> 58111.791 | AK8: =IF(Z8=0,0,AB8/Z8) -> 0.3909195 | AL8: =W8-AH8 -> 388711.79 | AM8: =IF(W8=0,0,AL8/W8) -> 0.4007338 | AN8: =AM8-S8 -> 0.060733805 | AO8: =Q8-P8 -> 3 | AP8: =IF(J8="Completed",0,MAX(0,Q8-AsOfDate)) -> 199 | AQ8: =SUMIFS(Invoices!$F$2:$F$2000,Invoices!$B$2:$B$2000,A8) -> 291000 | AR8: =SUMIFS(Invoices!$F$2:$F$2000,Invoices!$B$2:$B$2000,A8,Invoices!$K$2:$K$2000,"Paid") -> 97000 | AS8: =T8*W8-AQ8 -> 126100 | AT8: =COUNTIFS(RAID!$B$2:$B$2000,A8,RAID!$C$2:$C$2000,"Risk",RAID!$J$2:$J$2000,"<>Closed") -> 2 | AU8: =COUNTIFS(RAID!$B$2:$B$2000,A8,RAID!$C$2:$C$2000,"Issue",RAID!$J$2:$J$2000,"<>Closed") -> 0 | AV8: =SUMIFS(RAID!$Q$2:$Q$2000,RAID!$B$2:$B$2000,A8,RAID!$J$2:$J$2000,"<>Closed") -> 22800 | AW8: =COUNTIFS(ChangeRequests!$B$2:$B$1000,A8,ChangeRequests!$P$2:$P$1000,"Yes") -> 1 | AX8: =COUNTIFS(Allocations!$B$2:$B$2000,A8,Allocations!$K$2:$K$2000,"Yes") -> 5 | AY8: =IF(COUNTIFS(Milestones!$B$2:$B$2000,A8,Milestones!$L$2:$L$2000,"<>Completed")=0,"",_xlfn.MINIFS(Milestones!$F$2:$F$2000,Milestones!$B$2:$B$2000,A8,Milestones!$L$2:$L$2000,"<>Completed")) -> 46366 | AZ8: =IF(J8="Planned","N/A",IF(AK8-T8>RAG_CostRed,"Red",IF(AK8-T8>RAG_CostAmber,"Amber","Green"))) -> Green | BA8: =IF(J8="Planned","N/A",IF(AO8>RAG_ScheduleRedDays,"Red",IF(AO8>RAG_ScheduleAmberDays,"Amber","Green"))) -> Green | BB8: =IF(J8="Planned","N/A",IF(AM8<MarginFloor,"Red",IF(AM8<S8-MarginTolerance,"Amber","Green"))) -> Green | BC8: =IF(J8="Planned","N/A",IF(OR(AZ8="Red",BA8="Red",BB8="Red"),"Red",IF(OR(AZ8="Amber",BA8="Amber",BB8="Amber"),"Amber","Green"))) -> Green | BD8: =IF(J8="Planned","",MAX(0,ROUND(100-MAX(0,AK8-T8)*150-MAX(0,AO8)*0.4-MAX(0,S8-AM8)*150,0))) -> 99
A9: P-1008 | B9: Network Operations Centre Refresh | C9: C-108 | D9: =IFERROR(INDEX(Clients!$B$2:$B$200,MATCH(C9,Clients!$A$2:$A$200,0)),"Unknown client") -> Summit Telecom | E9: Cloud & Infrastructure | F9: Industrial | G9: E-0010 | H9: =IFERROR(INDEX(Resources!$B$2:$B$500,MATCH(G9,Resources!$A$2:$A$500,0)),"") -> Arjun Baptiste | I9: Trevor Nakamura | J9: Active | K9: Test & Deploy | L9: P2 | M9: Time & Materials | N9: 9 | O9: 46027 | P9: 46311 | Q9: 46328 | R9: 710000 | S9: 0.42 | T9: 0.85 | U9: 46270 | V9: =SUMIFS(ChangeRequests!$H$2:$H$1000,ChangeRequests!$B$2:$B$1000,A9,ChangeRequests!$G$2:$G$1000,"Approved") -> 55000 | W9: =R9+V9 -> 765000 | X9: =SUMIFS(Budget!$E$2:$E$2000,Budget!$B$2:$B$2000,A9) -> 498500 | Y9: =SUMIFS(ChangeRequests!$I$2:$I$1000,ChangeRequests!$B$2:$B$1000,A9,ChangeRequests!$G$2:$G$1000,"Approved") -> 38000 | Z9: =X9+Y9 -> 536500 | AA9: =SUMIFS(Actuals!$H$2:$H$6000,Actuals!$C$2:$C$6000,A9) -> 3581.3 | AB9: =SUMIFS(Actuals!$J$2:$J$6000,Actuals!$C$2:$C$6000,A9) -> 464449.86 | AC9: =IF(J9="Completed",1,IF(AsOfDate<=O9,0,MIN(1,(AsOfDate-O9)/MAX(1,P9-O9)))) -> 0.87676056 | AD9: =T9*Z9 -> 456025 | AE9: =AC9*Z9 -> 470382.04 | AF9: =IF(AB9=0,1,AD9/AB9) -> 0.98186056 | AG9: =IF(AE9=0,1,AD9/AE9) -> 0.96947791 | AH9: =IF(J9="Completed",AB9,IF(T9<0.05,MAX(Z9,AB9),AB9/T9)) -> 546411.6 | AI9: =MAX(0,AH9-AB9) -> 81961.74 | AJ9: =Z9-AH9 -> -9911.6 | AK9: =IF(Z9=0,0,AB9/Z9) -> 0.86570337 | AL9: =W9-AH9 -> 218588.4 | AM9: =IF(W9=0,0,AL9/W9) -> 0.28573647 | AN9: =AM9-S9 -> -0.13426353 | AO9: =Q9-P9 -> 17 | AP9: =IF(J9="Completed",0,MAX(0,Q9-AsOfDate)) -> 52 | AQ9: =SUMIFS(Invoices!$F$2:$F$2000,Invoices!$B$2:$B$2000,A9) -> 716418.97 | AR9: =SUMIFS(Invoices!$F$2:$F$2000,Invoices!$B$2:$B$2000,A9,Invoices!$K$2:$K$2000,"Paid") -> 639535.85 | AS9: =T9*W9-AQ9 -> -66168.97 | AT9: =COUNTIFS(RAID!$B$2:$B$2000,A9,RAID!$C$2:$C$2000,"Risk",RAID!$J$2:$J$2000,"<>Closed") -> 1 | AU9: =COUNTIFS(RAID!$B$2:$B$2000,A9,RAID!$C$2:$C$2000,"Issue",RAID!$J$2:$J$2000,"<>Closed") -> 0 | AV9: =SUMIFS(RAID!$Q$2:$Q$2000,RAID!$B$2:$B$2000,A9,RAID!$J$2:$J$2000,"<>Closed") -> 6000 | AW9: =COUNTIFS(ChangeRequests!$B$2:$B$1000,A9,ChangeRequests!$P$2:$P$1000,"Yes") -> 0 | AX9: =COUNTIFS(Allocations!$B$2:$B$2000,A9,Allocations!$K$2:$K$2000,"Yes") -> 4 | AY9: =IF(COUNTIFS(Milestones!$B$2:$B$2000,A9,Milestones!$L$2:$L$2000,"<>Completed")=0,"",_xlfn.MINIFS(Milestones!$F$2:$F$2000,Milestones!$B$2:$B$2000,A9,Milestones!$L$2:$L$2000,"<>Completed")) -> 46296 | AZ9: =IF(J9="Planned","N/A",IF(AK9-T9>RAG_CostRed,"Red",IF(AK9-T9>RAG_CostAmber,"Amber","Green"))) -> Green | BA9: =IF(J9="Planned","N/A",IF(AO9>RAG_ScheduleRedDays,"Red",IF(AO9>RAG_ScheduleAmberDays,"Amber","Green"))) -> Amber | BB9: =IF(J9="Planned","N/A",IF(AM9<MarginFloor,"Red",IF(AM9<S9-MarginTolerance,"Amber","Green"))) -> Amber | BC9: =IF(J9="Planned","N/A",IF(OR(AZ9="Red",BA9="Red",BB9="Red"),"Red",IF(OR(AZ9="Amber",BA9="Amber",BB9="Amber"),"Amber","Green"))) -> Amber | BD9: =IF(J9="Planned","",MAX(0,ROUND(100-MAX(0,AK9-T9)*150-MAX(0,AO9)*0.4-MAX(0,S9-AM9)*150,0))) -> 71
A10: P-1009 | B10: Smart Factory IoT Pilot | C10: C-109 | D10: =IFERROR(INDEX(Clients!$B$2:$B$200,MATCH(C10,Clients!$A$2:$A$200,0)),"Unknown client") -> Granite Manufacturing | E10: Operational Excellence | F10: Industrial | G10: E-0005 | H10: =IFERROR(INDEX(Resources!$B$2:$B$500,MATCH(G10,Resources!$A$2:$A$500,0)),"") -> Mei Fraser | I10: Greg Kowalski | J10: Active | K10: Execute | L10: P2 | M10: Fixed Price | N10: 10 | O10: 46146 | P10: 46367 | Q10: 46370 | R10: 535000 | S10: 0.36 | T10: 0.5 | U10: 46269 | V10: =SUMIFS(ChangeRequests!$H$2:$H$1000,ChangeRequests!$B$2:$B$1000,A10,ChangeRequests!$G$2:$G$1000,"Approved") -> 0 | W10: =R10+V10 -> 535000 | X10: =SUMIFS(Budget!$E$2:$E$2000,Budget!$B$2:$B$2000,A10) -> 342700 | Y10: =SUMIFS(ChangeRequests!$I$2:$I$1000,ChangeRequests!$B$2:$B$1000,A10,ChangeRequests!$G$2:$G$1000,"Approved") -> 0 | Z10: =X10+Y10 -> 342700 | AA10: =SUMIFS(Actuals!$H$2:$H$6000,Actuals!$C$2:$C$6000,A10) -> 1798 | AB10: =SUMIFS(Actuals!$J$2:$J$6000,Actuals!$C$2:$C$6000,A10) -> 160755.53 | AC10: =IF(J10="Completed",1,IF(AsOfDate<=O10,0,MIN(1,(AsOfDate-O10)/MAX(1,P10-O10)))) -> 0.58823529 | AD10: =T10*Z10 -> 171350 | AE10: =AC10*Z10 -> 201588.24 | AF10: =IF(AB10=0,1,AD10/AB10) -> 1.0659042 | AG10: =IF(AE10=0,1,AD10/AE10) -> 0.85 | AH10: =IF(J10="Completed",AB10,IF(T10<0.05,MAX(Z10,AB10),AB10/T10)) -> 321511.06 | AI10: =MAX(0,AH10-AB10) -> 160755.53 | AJ10: =Z10-AH10 -> 21188.94 | AK10: =IF(Z10=0,0,AB10/Z10) -> 0.46908529 | AL10: =W10-AH10 -> 213488.94 | AM10: =IF(W10=0,0,AL10/W10) -> 0.39904475 | AN10: =AM10-S10 -> 0.039044748 | AO10: =Q10-P10 -> 3 | AP10: =IF(J10="Completed",0,MAX(0,Q10-AsOfDate)) -> 94 | AQ10: =SUMIFS(Invoices!$F$2:$F$2000,Invoices!$B$2:$B$2000,A10) -> 160500 | AR10: =SUMIFS(Invoices!$F$2:$F$2000,Invoices!$B$2:$B$2000,A10,Invoices!$K$2:$K$2000,"Paid") -> 160500 | AS10: =T10*W10-AQ10 -> 107000 | AT10: =COUNTIFS(RAID!$B$2:$B$2000,A10,RAID!$C$2:$C$2000,"Risk",RAID!$J$2:$J$2000,"<>Closed") -> 1 | AU10: =COUNTIFS(RAID!$B$2:$B$2000,A10,RAID!$C$2:$C$2000,"Issue",RAID!$J$2:$J$2000,"<>Closed") -> 1 | AV10: =SUMIFS(RAID!$Q$2:$Q$2000,RAID!$B$2:$B$2000,A10,RAID!$J$2:$J$2000,"<>Closed") -> 70600 | AW10: =COUNTIFS(ChangeRequests!$B$2:$B$1000,A10,ChangeRequests!$P$2:$P$1000,"Yes") -> 0 | AX10: =COUNTIFS(Allocations!$B$2:$B$2000,A10,Allocations!$K$2:$K$2000,"Yes") -> 6 | AY10: =IF(COUNTIFS(Milestones!$B$2:$B$2000,A10,Milestones!$L$2:$L$2000,"<>Completed")=0,"",_xlfn.MINIFS(Milestones!$F$2:$F$2000,Milestones!$B$2:$B$2000,A10,Milestones!$L$2:$L$2000,"<>Completed")) -> 46301 | AZ10: =IF(J10="Planned","N/A",IF(AK10-T10>RAG_CostRed,"Red",IF(AK10-T10>RAG_CostAmber,"Amber","Green"))) -> Green | BA10: =IF(J10="Planned","N/A",IF(AO10>RAG_ScheduleRedDays,"Red",IF(AO10>RAG_ScheduleAmberDays,"Amber","Green"))) -> Green | BB10: =IF(J10="Planned","N/A",IF(AM10<MarginFloor,"Red",IF(AM10<S10-MarginTolerance,"Amber","Green"))) -> Green | BC10: =IF(J10="Planned","N/A",IF(OR(AZ10="Red",BA10="Red",BB10="Red"),"Red",IF(OR(AZ10="Amber",BA10="Amber",BB10="Amber"),"Amber","Green"))) -> Green | BD10: =IF(J10="Planned","",MAX(0,ROUND(100-MAX(0,AK10-T10)*150-MAX(0,AO10)*0.4-MAX(0,S10-AM10)*150,0))) -> 99
A11: P-1010 | B11: 311 Citizen Services App | C11: C-110 | D11: =IFERROR(INDEX(Clients!$B$2:$B$200,MATCH(C11,Clients!$A$2:$A$200,0)),"Unknown client") -> Bluewater Municipal Services | E11: Customer Experience | F11: Health & Public | G11: E-0007 | H11: =IFERROR(INDEX(Resources!$B$2:$B$500,MATCH(G11,Resources!$A$2:$A$500,0)),"") -> Fatima Cohen | I11: Mayor's Office - D. Price | J11: Active | K11: Test & Deploy | L11: P2 | M11: Fixed Price | N11: 10 | O11: 45992 | P11: 46262 | Q11: 46311 | R11: 735000 | S11: 0.38 | T11: 0.86 | U11: 46273 | V11: =SUMIFS(ChangeRequests!$H$2:$H$1000,ChangeRequests!$B$2:$B$1000,A11,ChangeRequests!$G$2:$G$1000,"Approved") -> 30000 | W11: =R11+V11 -> 765000 | X11: =SUMIFS(Budget!$E$2:$E$2000,Budget!$B$2:$B$2000,A11) -> 455000 | Y11: =SUMIFS(ChangeRequests!$I$2:$I$1000,ChangeRequests!$B$2:$B$1000,A11,ChangeRequests!$G$2:$G$1000,"Approved") -> 42000 | Z11: =X11+Y11 -> 497000 | AA11: =SUMIFS(Actuals!$H$2:$H$6000,Actuals!$C$2:$C$6000,A11) -> 5522.3 | AB11: =SUMIFS(Actuals!$J$2:$J$6000,Actuals!$C$2:$C$6000,A11) -> 513842.3 | AC11: =IF(J11="Completed",1,IF(AsOfDate<=O11,0,MIN(1,(AsOfDate-O11)/MAX(1,P11-O11)))) -> 1 | AD11: =T11*Z11 -> 427420 | AE11: =AC11*Z11 -> 497000 | AF11: =IF(AB11=0,1,AD11/AB11) -> 0.83181163 | AG11: =IF(AE11=0,1,AD11/AE11) -> 0.86 | AH11: =IF(J11="Completed",AB11,IF(T11<0.05,MAX(Z11,AB11),AB11/T11)) -> 597491.05 | AI11: =MAX(0,AH11-AB11) -> 83648.747 | AJ11: =Z11-AH11 -> -100491.05 | AK11: =IF(Z11=0,0,AB11/Z11) -> 1.0338879 | AL11: =W11-AH11 -> 167508.95 | AM11: =IF(W11=0,0,AL11/W11) -> 0.21896595 | AN11: =AM11-S11 -> -0.16103405 | AO11: =Q11-P11 -> 49 | AP11: =IF(J11="Completed",0,MAX(0,Q11-AsOfDate)) -> 35 | AQ11: =SUMIFS(Invoices!$F$2:$F$2000,Invoices!$B$2:$B$2000,A11) -> 441000 | AR11: =SUMIFS(Invoices!$F$2:$F$2000,Invoices!$B$2:$B$2000,A11,Invoices!$K$2:$K$2000,"Paid") -> 220500 | AS11: =T11*W11-AQ11 -> 216900 | AT11: =COUNTIFS(RAID!$B$2:$B$2000,A11,RAID!$C$2:$C$2000,"Risk",RAID!$J$2:$J$2000,"<>Closed") -> 2 | AU11: =COUNTIFS(RAID!$B$2:$B$2000,A11,RAID!$C$2:$C$2000,"Issue",RAID!$J$2:$J$2000,"<>Closed") -> 1 | AV11: =SUMIFS(RAID!$Q$2:$Q$2000,RAID!$B$2:$B$2000,A11,RAID!$J$2:$J$2000,"<>Closed") -> 286400 | AW11: =COUNTIFS(ChangeRequests!$B$2:$B$1000,A11,ChangeRequests!$P$2:$P$1000,"Yes") -> 0 | AX11: =COUNTIFS(Allocations!$B$2:$B$2000,A11,Allocations!$K$2:$K$2000,"Yes") -> 4 | AY11: =IF(COUNTIFS(Milestones!$B$2:$B$2000,A11,Milestones!$L$2:$L$2000,"<>Completed")=0,"",_xlfn.MINIFS(Milestones!$F$2:$F$2000,Milestones!$B$2:$B$2000,A11,Milestones!$L$2:$L$2000,"<>Completed")) -> 46267 | AZ11: =IF(J11="Planned","N/A",IF(AK11-T11>RAG_CostRed,"Red",IF(AK11-T11>RAG_CostAmber,"Amber","Green"))) -> Amber | BA11: =IF(J11="Planned","N/A",IF(AO11>RAG_ScheduleRedDays,"Red",IF(AO11>RAG_ScheduleAmberDays,"Amber","Green"))) -> Red | BB11: =IF(J11="Planned","N/A",IF(AM11<MarginFloor,"Red",IF(AM11<S11-MarginTolerance,"Amber","Green"))) -> Amber | BC11: =IF(J11="Planned","N/A",IF(OR(AZ11="Red",BA11="Red",BB11="Red"),"Red",IF(OR(AZ11="Amber",BA11="Amber",BB11="Amber"),"Amber","Green"))) -> Red | BD11: =IF(J11="Planned","",MAX(0,ROUND(100-MAX(0,AK11-T11)*150-MAX(0,AO11)*0.4-MAX(0,S11-AM11)*150,0))) -> 30
A12: P-1011 | B12: Clinical Trials Data Hub | C12: C-111 | D12: =IFERROR(INDEX(Clients!$B$2:$B$200,MATCH(C12,Clients!$A$2:$A$200,0)),"Unknown client") -> Evergreen Pharma | E12: Data & AI | F12: Health & Public | G12: E-0006 | H12: =IFERROR(INDEX(Resources!$B$2:$B$500,MATCH(G12,Resources!$A$2:$A$500,0)),"") -> Noah Rahimi | I12: Dr. Mira Castellano | J12: Active | K12: Execute | L12: P3 | M12: Time & Materials | N12: 6 | O12: 46069 | P12: 46507 | Q12: 46507 | R12: 975000 | S12: 0.42 | T12: 0.42 | U12: 46272 | V12: =SUMIFS(ChangeRequests!$H$2:$H$1000,ChangeRequests!$B$2:$B$1000,A12,ChangeRequests!$G$2:$G$1000,"Approved") -> 75000 | W12: =R12+V12 -> 1050000 | X12: =SUMIFS(Budget!$E$2:$E$2000,Budget!$B$2:$B$2000,A12) -> 620700 | Y12: =SUMIFS(ChangeRequests!$I$2:$I$1000,ChangeRequests!$B$2:$B$1000,A12,ChangeRequests!$G$2:$G$1000,"Approved") -> 48000 | Z12: =X12+Y12 -> 668700 | AA12: =SUMIFS(Actuals!$H$2:$H$6000,Actuals!$C$2:$C$6000,A12) -> 2296.3 | AB12: =SUMIFS(Actuals!$J$2:$J$6000,Actuals!$C$2:$C$6000,A12) -> 248297.41 | AC12: =IF(J12="Completed",1,IF(AsOfDate<=O12,0,MIN(1,(AsOfDate-O12)/MAX(1,P12-O12)))) -> 0.47260274 | AD12: =T12*Z12 -> 280854 | AE12: =AC12*Z12 -> 316029.45 | AF12: =IF(AB12=0,1,AD12/AB12) -> 1.1311193 | AG12: =IF(AE12=0,1,AD12/AE12) -> 0.88869565 | AH12: =IF(J12="Completed",AB12,IF(T12<0.05,MAX(Z12,AB12),AB12/T12)) -> 591184.31 | AI12: =MAX(0,AH12-AB12) -> 342886.9 | AJ12: =Z12-AH12 -> 77515.69 | AK12: =IF(Z12=0,0,AB12/Z12) -> 0.37131361 | AL12: =W12-AH12 -> 458815.69 | AM12: =IF(W12=0,0,AL12/W12) -> 0.43696732 | AN12: =AM12-S12 -> 0.016967324 | AO12: =Q12-P12 -> 0 | AP12: =IF(J12="Completed",0,MAX(0,Q12-AsOfDate)) -> 231 | AQ12: =SUMIFS(Invoices!$F$2:$F$2000,Invoices!$B$2:$B$2000,A12) -> 415431.38 | AR12: =SUMIFS(Invoices!$F$2:$F$2000,Invoices!$B$2:$B$2000,A12,Invoices!$K$2:$K$2000,"Paid") -> 263059.05 | AS12: =T12*W12-AQ12 -> 25568.62 | AT12: =COUNTIFS(RAID!$B$2:$B$2000,A12,RAID!$C$2:$C$2000,"Risk",RAID!$J$2:$J$2000,"<>Closed") -> 1 | AU12: =COUNTIFS(RAID!$B$2:$B$2000,A12,RAID!$C$2:$C$2000,"Issue",RAID!$J$2:$J$2000,"<>Closed") -> 0 | AV12: =SUMIFS(RAID!$Q$2:$Q$2000,RAID!$B$2:$B$2000,A12,RAID!$J$2:$J$2000,"<>Closed") -> 25200 | AW12: =COUNTIFS(ChangeRequests!$B$2:$B$1000,A12,ChangeRequests!$P$2:$P$1000,"Yes") -> 0 | AX12: =COUNTIFS(Allocations!$B$2:$B$2000,A12,Allocations!$K$2:$K$2000,"Yes") -> 6 | AY12: =IF(COUNTIFS(Milestones!$B$2:$B$2000,A12,Milestones!$L$2:$L$2000,"<>Completed")=0,"",_xlfn.MINIFS(Milestones!$F$2:$F$2000,Milestones!$B$2:$B$2000,A12,Milestones!$L$2:$L$2000,"<>Completed")) -> 46374 | AZ12: =IF(J12="Planned","N/A",IF(AK12-T12>RAG_CostRed,"Red",IF(AK12-T12>RAG_CostAmber,"Amber","Green"))) -> Green | BA12: =IF(J12="Planned","N/A",IF(AO12>RAG_ScheduleRedDays,"Red",IF(AO12>RAG_ScheduleAmberDays,"Amber","Green"))) -> Green | BB12: =IF(J12="Planned","N/A",IF(AM12<MarginFloor,"Red",IF(AM12<S12-MarginTolerance,"Amber","Green"))) -> Green | BC12: =IF(J12="Planned","N/A",IF(OR(AZ12="Red",BA12="Red",BB12="Red"),"Red",IF(OR(AZ12="Amber",BA12="Amber",BB12="Amber"),"Amber","Green"))) -> Green | BD12: =IF(J12="Planned","",MAX(0,ROUND(100-MAX(0,AK12-T12)*150-MAX(0,AO12)*0.4-MAX(0,S12-AM12)*150,0))) -> 100
A13: P-1012 | B13: Grid Analytics Dashboard | C13: C-112 | D13: =IFERROR(INDEX(Clients!$B$2:$B$200,MATCH(C13,Clients!$A$2:$A$200,0)),"Unknown client") -> Lakeshore Energy | E13: Data & AI | F13: Industrial | G13: E-0010 | H13: =IFERROR(INDEX(Resources!$B$2:$B$500,MATCH(G13,Resources!$A$2:$A$500,0)),"") -> Arjun Baptiste | I13: Alan Fortier | J13: Active | K13: Execute | L13: P2 | M13: Fixed Price | N13: 5 | O13: 46174 | P13: 46374 | Q13: 46374 | R13: 510000 | S13: 0.32 | T13: 0.44 | U13: 46271 | V13: =SUMIFS(ChangeRequests!$H$2:$H$1000,ChangeRequests!$B$2:$B$1000,A13,ChangeRequests!$G$2:$G$1000,"Approved") -> 0 | W13: =R13+V13 -> 510000 | X13: =SUMIFS(Budget!$E$2:$E$2000,Budget!$B$2:$B$2000,A13) -> 346500 | Y13: =SUMIFS(ChangeRequests!$I$2:$I$1000,ChangeRequests!$B$2:$B$1000,A13,ChangeRequests!$G$2:$G$1000,"Approved") -> 0 | Z13: =X13+Y13 -> 346500 | AA13: =SUMIFS(Actuals!$H$2:$H$6000,Actuals!$C$2:$C$6000,A13) -> 1289.2 | AB13: =SUMIFS(Actuals!$J$2:$J$6000,Actuals!$C$2:$C$6000,A13) -> 142260.82 | AC13: =IF(J13="Completed",1,IF(AsOfDate<=O13,0,MIN(1,(AsOfDate-O13)/MAX(1,P13-O13)))) -> 0.51 | AD13: =T13*Z13 -> 152460 | AE13: =AC13*Z13 -> 176715 | AF13: =IF(AB13=0,1,AD13/AB13) -> 1.0716935 | AG13: =IF(AE13=0,1,AD13/AE13) -> 0.8627451 | AH13: =IF(J13="Completed",AB13,IF(T13<0.05,MAX(Z13,AB13),AB13/T13)) -> 323320.05 | AI13: =MAX(0,AH13-AB13) -> 181059.23 | AJ13: =Z13-AH13 -> 23179.955 | AK13: =IF(Z13=0,0,AB13/Z13) -> 0.41056514 | AL13: =W13-AH13 -> 186679.95 | AM13: =IF(W13=0,0,AL13/W13) -> 0.36603913 | AN13: =AM13-S13 -> 0.046039127 | AO13: =Q13-P13 -> 0 | AP13: =IF(J13="Completed",0,MAX(0,Q13-AsOfDate)) -> 98 | AQ13: =SUMIFS(Invoices!$F$2:$F$2000,Invoices!$B$2:$B$2000,A13) -> 153000 | AR13: =SUMIFS(Invoices!$F$2:$F$2000,Invoices!$B$2:$B$2000,A13,Invoices!$K$2:$K$2000,"Paid") -> 153000 | AS13: =T13*W13-AQ13 -> 71400 | AT13: =COUNTIFS(RAID!$B$2:$B$2000,A13,RAID!$C$2:$C$2000,"Risk",RAID!$J$2:$J$2000,"<>Closed") -> 0 | AU13: =COUNTIFS(RAID!$B$2:$B$2000,A13,RAID!$C$2:$C$2000,"Issue",RAID!$J$2:$J$2000,"<>Closed") -> 0 | AV13: =SUMIFS(RAID!$Q$2:$Q$2000,RAID!$B$2:$B$2000,A13,RAID!$J$2:$J$2000,"<>Closed") -> 0 | AW13: =COUNTIFS(ChangeRequests!$B$2:$B$1000,A13,ChangeRequests!$P$2:$P$1000,"Yes") -> 0 | AX13: =COUNTIFS(Allocations!$B$2:$B$2000,A13,Allocations!$K$2:$K$2000,"Yes") -> 6 | AY13: =IF(COUNTIFS(Milestones!$B$2:$B$2000,A13,Milestones!$L$2:$L$2000,"<>Completed")=0,"",_xlfn.MINIFS(Milestones!$F$2:$F$2000,Milestones!$B$2:$B$2000,A13,Milestones!$L$2:$L$2000,"<>Completed")) -> 46314 | AZ13: =IF(J13="Planned","N/A",IF(AK13-T13>RAG_CostRed,"Red",IF(AK13-T13>RAG_CostAmber,"Amber","Green"))) -> Green | BA13: =IF(J13="Planned","N/A",IF(AO13>RAG_ScheduleRedDays,"Red",IF(AO13>RAG_ScheduleAmberDays,"Amber","Green"))) -> Green | BB13: =IF(J13="Planned","N/A",IF(AM13<MarginFloor,"Red",IF(AM13<S13-MarginTolerance,"Amber","Green"))) -> Green | BC13: =IF(J13="Planned","N/A",IF(OR(AZ13="Red",BA13="Red",BB13="Red"),"Red",IF(OR(AZ13="Amber",BA13="Amber",BB13="Amber"),"Amber","Green"))) -> Green | BD13: =IF(J13="Planned","",MAX(0,ROUND(100-MAX(0,AK13-T13)*150-MAX(0,AO13)*0.4-MAX(0,S13-AM13)*150,0))) -> 100
... A25: P-1024 | B25: Municipal Asset Management | C25: C-110 | D25: =IFERROR(INDEX(Clients!$B$2:$B$200,MATCH(C25,Clients!$A$2:$A$200,0)),"Unknown client") -> Bluewater Municipal Services | E25: Digital Transformation | F25: Health & Public | G25: E-0005 | H25: =IFERROR(INDEX(Resources!$B$2:$B$500,MATCH(G25,Resources!$A$2:$A$500,0)),"") -> Mei Fraser | I25: Mayor's Office - D. Price | J25: Planned | K25: Initiate | L25: P2 | M25: Fixed Price | N25: 9 | O25: 46398 | P25: 46689 | Q25: 46689 | R25: 1090000 | S25: 0.36 | T25: 0 | U25: 46252 | V25: =SUMIFS(ChangeRequests!$H$2:$H$1000,ChangeRequests!$B$2:$B$1000,A25,ChangeRequests!$G$2:$G$1000,"Approved") -> 0 | W25: =R25+V25 -> 1090000 | X25: =SUMIFS(Budget!$E$2:$E$2000,Budget!$B$2:$B$2000,A25) -> 698500 | Y25: =SUMIFS(ChangeRequests!$I$2:$I$1000,ChangeRequests!$B$2:$B$1000,A25,ChangeRequests!$G$2:$G$1000,"Approved") -> 0 | Z25: =X25+Y25 -> 698500 | AA25: =SUMIFS(Actuals!$H$2:$H$6000,Actuals!$C$2:$C$6000,A25) -> 0 | AB25: =SUMIFS(Actuals!$J$2:$J$6000,Actuals!$C$2:$C$6000,A25) -> 0 | AC25: =IF(J25="Completed",1,IF(AsOfDate<=O25,0,MIN(1,(AsOfDate-O25)/MAX(1,P25-O25)))) -> 0 | AD25: =T25*Z25 -> 0 | AE25: =AC25*Z25 -> 0 | AF25: =IF(AB25=0,1,AD25/AB25) -> 1 | AG25: =IF(AE25=0,1,AD25/AE25) -> 1 | AH25: =IF(J25="Completed",AB25,IF(T25<0.05,MAX(Z25,AB25),AB25/T25)) -> 698500 | AI25: =MAX(0,AH25-AB25) -> 698500 | AJ25: =Z25-AH25 -> 0 | AK25: =IF(Z25=0,0,AB25/Z25) -> 0 | AL25: =W25-AH25 -> 391500 | AM25: =IF(W25=0,0,AL25/W25) -> 0.35917431 | AN25: =AM25-S25 -> -0.00082568807 | AO25: =Q25-P25 -> 0 | AP25: =IF(J25="Completed",0,MAX(0,Q25-AsOfDate)) -> 413 | AQ25: =SUMIFS(Invoices!$F$2:$F$2000,Invoices!$B$2:$B$2000,A25) -> 0 | AR25: =SUMIFS(Invoices!$F$2:$F$2000,Invoices!$B$2:$B$2000,A25,Invoices!$K$2:$K$2000,"Paid") -> 0 | AS25: =T25*W25-AQ25 -> 0 | AT25: =COUNTIFS(RAID!$B$2:$B$2000,A25,RAID!$C$2:$C$2000,"Risk",RAID!$J$2:$J$2000,"<>Closed") -> 0 | AU25: =COUNTIFS(RAID!$B$2:$B$2000,A25,RAID!$C$2:$C$2000,"Issue",RAID!$J$2:$J$2000,"<>Closed") -> 0 | AV25: =SUMIFS(RAID!$Q$2:$Q$2000,RAID!$B$2:$B$2000,A25,RAID!$J$2:$J$2000,"<>Closed") -> 0 | AW25: =COUNTIFS(ChangeRequests!$B$2:$B$1000,A25,ChangeRequests!$P$2:$P$1000,"Yes") -> 0 | AX25: =COUNTIFS(Allocations!$B$2:$B$2000,A25,Allocations!$K$2:$K$2000,"Yes") -> 0 | AY25: =IF(COUNTIFS(Milestones!$B$2:$B$2000,A25,Milestones!$L$2:$L$2000,"<>Completed")=0,"",_xlfn.MINIFS(Milestones!$F$2:$F$2000,Milestones!$B$2:$B$2000,A25,Milestones!$L$2:$L$2000,"<>Completed")) -> 46427 | AZ25: =IF(J25="Planned","N/A",IF(AK25-T25>RAG_CostRed,"Red",IF(AK25-T25>RAG_CostAmber,"Amber","Green"))) -> N/A | BA25: =IF(J25="Planned","N/A",IF(AO25>RAG_ScheduleRedDays,"Red",IF(AO25>RAG_ScheduleAmberDays,"Amber","Green"))) -> N/A | BB25: =IF(J25="Planned","N/A",IF(AM25<MarginFloor,"Red",IF(AM25<S25-MarginTolerance,"Amber","Green"))) -> N/A | BC25: =IF(J25="Planned","N/A",IF(OR(AZ25="Red",BA25="Red",BB25="Red"),"Red",IF(OR(AZ25="Amber",BA25="Amber",BB25="Amber"),"Amber","Green"))) -> N/A | BD25: =IF(J25="Planned","",MAX(0,ROUND(100-MAX(0,AK25-T25)*150-MAX(0,AO25)*0.4-MAX(0,S25-AM25)*150,0)))

Sheet Resources
A1: EmployeeID | B1: FullName | C1: Role | D1: Department | E1: Level | F1: Location | G1: EmploymentType | H1: CostRateHr | I1: BillRateHr | J1: WeeklyCapacityHrs | K1: ManagerID | L1: ManagerName | M1: PrimarySkill | N1: StartDate | O1: CurrentAllocationPct | P1: ActiveAssignments | Q1: AvailableHrsPerWeek | R1: UtilizationStatus | S1: HoursLoggedYTD | T1: BillableHoursYTD | U1: BillableRatioYTD
A2: E-0001 | B2: Helena Marsh | C2: Director, Delivery | D2: PMO | E2: L7 | F2: Toronto | G2: FTE | H2: 135 | I2: 0 | J2: 0 | L2: =IFERROR(INDEX(Resources!$B$2:$B$500,MATCH(K2,Resources!$A$2:$A$500,0)),"") | M2: Portfolio governance | N2: 42436 | O2: =SUMIFS(Allocations!$J$2:$J$2000,Allocations!$D$2:$D$2000,A2,Allocations!$H$2:$H$2000,"<="&AsOfDate,Allocations!$I$2:$I$2000,">="&AsOfDate) -> 0 | P2: =COUNTIFS(Allocations!$D$2:$D$2000,A2,Allocations!$H$2:$H$2000,"<="&AsOfDate,Allocations!$I$2:$I$2000,">="&AsOfDate) -> 0 | Q2: =ROUND(J2*MAX(0,1-O2),1) -> 0 | R2: =IF(J2=0,"Non-assignable",IF(O2>OverallocationThreshold,"Overallocated",IF(O2<UnderutilizationThreshold,"Under-utilized","Healthy"))) -> Non-assignable | S2: =SUMIFS(Actuals!$H$2:$H$6000,Actuals!$E$2:$E$6000,A2,Actuals!$B$2:$B$6000,">="&DATE(YEAR(AsOfDate),1,1)) -> 0 | T2: =SUMIFS(Actuals!$H$2:$H$6000,Actuals!$E$2:$E$6000,A2,Actuals!$B$2:$B$6000,">="&DATE(YEAR(AsOfDate),1,1),Actuals!$I$2:$I$6000,"Yes") -> 0 | U2: =IF(S2=0,0,T2/S2) -> 0
A3: E-0002 | B3: Gordon Achebe | C3: Director, Engineering | D3: Engineering | E3: L7 | F3: Toronto | G3: FTE | H3: 140 | I3: 0 | J3: 0 | L3: =IFERROR(INDEX(Resources!$B$2:$B$500,MATCH(K3,Resources!$A$2:$A$500,0)),"") | M3: Engineering leadership | N3: 42989 | O3: =SUMIFS(Allocations!$J$2:$J$2000,Allocations!$D$2:$D$2000,A3,Allocations!$H$2:$H$2000,"<="&AsOfDate,Allocations!$I$2:$I$2000,">="&AsOfDate) -> 0 | P3: =COUNTIFS(Allocations!$D$2:$D$2000,A3,Allocations!$H$2:$H$2000,"<="&AsOfDate,Allocations!$I$2:$I$2000,">="&AsOfDate) -> 0 | Q3: =ROUND(J3*MAX(0,1-O3),1) -> 0 | R3: =IF(J3=0,"Non-assignable",IF(O3>OverallocationThreshold,"Overallocated",IF(O3<UnderutilizationThreshold,"Under-utilized","Healthy"))) -> Non-assignable | S3: =SUMIFS(Actuals!$H$2:$H$6000,Actuals!$E$2:$E$6000,A3,Actuals!$B$2:$B$6000,">="&DATE(YEAR(AsOfDate),1,1)) -> 0 | T3: =SUMIFS(Actuals!$H$2:$H$6000,Actuals!$E$2:$E$6000,A3,Actuals!$B$2:$B$6000,">="&DATE(YEAR(AsOfDate),1,1),Actuals!$I$2:$I$6000,"Yes") -> 0 | U3: =IF(S3=0,0,T3/S3) -> 0
A4: E-0003 | B4: Aisha Tremblay | C4: Project Manager | D4: PMO | E4: L6 | F4: Toronto | G4: FTE | H4: 102.08 | I4: 205 | J4: 40 | K4: E-0001 | L4: =IFERROR(INDEX(Resources!$B$2:$B$500,MATCH(K4,Resources!$A$2:$A$500,0)),"") -> Helena Marsh | M4: Stakeholder mgmt | N4: 44614 | O4: =SUMIFS(Allocations!$J$2:$J$2000,Allocations!$D$2:$D$2000,A4,Allocations!$H$2:$H$2000,"<="&AsOfDate,Allocations!$I$2:$I$2000,">="&AsOfDate) -> 0.75 | P4: =COUNTIFS(Allocations!$D$2:$D$2000,A4,Allocations!$H$2:$H$2000,"<="&AsOfDate,Allocations!$I$2:$I$2000,">="&AsOfDate) -> 2 | Q4: =ROUND(J4*MAX(0,1-O4),1) -> 10 | R4: =IF(J4=0,"Non-assignable",IF(O4>OverallocationThreshold,"Overallocated",IF(O4<UnderutilizationThreshold,"Under-utilized","Healthy"))) -> Healthy | S4: =SUMIFS(Actuals!$H$2:$H$6000,Actuals!$E$2:$E$6000,A4,Actuals!$B$2:$B$6000,">="&DATE(YEAR(AsOfDate),1,1)) -> 876.7 | T4: =SUMIFS(Actuals!$H$2:$H$6000,Actuals!$E$2:$E$6000,A4,Actuals!$B$2:$B$6000,">="&DATE(YEAR(AsOfDate),1,1),Actuals!$I$2:$I$6000,"Yes") -> 673.1 | U4: =IF(S4=0,0,T4/S4) -> 0.76776548
